<?xml version="1.0" ?>
<mujoco>
  <!-- Just infer inertia from geometry since we're not going to be rotating the mass -->
  <compiler angle="radian" coordinate="local" inertiafromgeom="true" />
  <option integrator="RK4" timestep="0.02" />

  <default>
    <joint armature="0" damping="0" limited="false" />
    <!-- Default geom is collisionless -->
    <geom conaffinity="2" condim="3" density="100" friction="1 0.5 0.5" margin="0" rgba="1 1 0.5 0.7" material="mat-geom-default"/>
  </default>

  <asset>
    <texture type="skybox" builtin="gradient" height="100" width="100" rgb1="1 1 1" rgb2="0 0 0" />
    <texture name="tex-geom" type="cube" builtin="flat" height="1278" width="127" mark="cross" markrgb="0.3 0.3 0.3" random="0.01" rgb1="0.8 0.6 0.4" rgb2="0.8 0.6 0.4" />
    <texture name="tex-target" type="cube" builtin="flat" height="1278" width="127" mark="cross" markrgb="0.3 0.3 0.3" random="0.01" rgb1="0.2 1.0 0.2" rgb2="0.2 1.0 0.2" />
    <texture name="tex-floor" type="2d" builtin="checker" height="100" width="100" rgb1="0 0 0" rgb2="0.8 0.8 0.8" />
    <material name="mat-floor" reflectance="0.5" shininess="1" specular="1" texrepeat="30 30" texture="tex-floor" />
    <material name="mat-geom-default" texture="tex-geom" texuniform="true" />
    <material name="mat-target" texture="tex-target" texuniform="true" />
  </asset>

  <worldbody>
    <light cutoff="100" diffuse="1 1 1" dir="-0 0 -1.3" directional="true" exponent="1" pos="0 0 1.3" specular=".1 .1 .1" />
    <geom name="floor" type="plane" conaffinity="1" condim="3" pos="0 0 0" rgba="0.8 0.9 0.8 1" size="40 40 40" material="mat-floor" />
    <!-- Point mass with spherical collision geometry -->
    <body name="ball" pos="0 0 0">
      <geom name="ball-geom" type="sphere" conaffinity="2" size="1" pos="0 0 1" />
      <joint name="joint-ballx" type="slide" axis="1 0 0" pos="0 0 0" />
      <joint name="joint-bally" type="slide" axis="0 1 0" pos="0 0 0" />
    </body>
    <!-- Collisionless target limited to x-y plane -->
    <body name="target" pos="2 0 0">
      <geom name="target-geom" type="sphere" conaffinity="0" size="1" pos="0 0 1" material="mat-target" />
      <joint name="joint-targetx" type="slide" axis="1 0 0" pos="0 0 0" />
      <joint name="joint-targety" type="slide" axis="0 1 0" pos="0 0 0" />
    </body>
  </worldbody>

  <actuator>
    <!-- All actuators should have a control range as a force limiter -->
    <motor name="actuator-x" gear="500" joint="joint-ballx" />
    <motor name="actuator-y" gear="500" joint="joint-bally" />
  </actuator>

  <sensor>
  </sensor>

</mujoco>
